## 异步编程模型里的异常处理链条

### 1. 如果某个函数返回的是 Promise 的话，那么就使用 async和await来简化异常链条

- 如果某个函数返回的是promise，在其他函数调用的时候，就加上await，然后就能 try... catch，那么异步的异常处理就和同步的没有区别了。
  - 两个条件都要满足，try..catch才能捕捉到错误。
  - 1. 函数返回Promise   2. 调用下面函数的函数使用async 和 await
- 注意：**当连续几个函数调用的时候，每一步如果有异步的操作，都要加上async await**
  - 如果在一个函数调用链中，有异步的操作，必须加上await

```js
async function func2() {         // 调用下面函数的这个函数使用async await
  try {      										 // 然后就能通过try...catch捕捉到错误
    await func3();
  } catch (error) {
    console.log('error');
  }
}

// Promise async await

function func3() {
  return new Promise((resolve, reject) => {     // 这个函数返回的是Promise
    setTimeout(function() {
      const r = Math.random();
      if(r < 0.5) {
        reject('error async');
      }
    })
  })
}
```



#### 现在koa的各种库返回的都是封装好的Promise，所以我们就不需要自己封装Promise了，所以直接在调用函数的地方使用async await 和 try...catch就能捕捉到异常！！！



**如果我们把try里面的await去掉，会报错说: Unhandled promise rejections，没有处理promise的rejections异常，当我们加上await后，才能监听到promise的rejections，然后catch捕获到**

```js
async function func2() {         // 调用下面函数的这个函数使用async await
  try {      										 // 然后就能通过try...catch捕捉到错误
    func3();
  } catch (error) {
    console.log('error');
  }
}

// Promise async await

function func3() {
  return new Promise((resolve, reject) => {     // 这个函数返回的是Promise
    setTimeout(function() {
      const r = Math.random();
      if(r < 0.5) {
        reject('error async');
      }
    })
  })
}
```



